-----
### 메서드에 예외 선언하기
-----
1. 메서드에 예외를 선언하려면, 메서드 선언부에 키워드 throws를 사용해서 메서드 내에서 발생할 수 있는 예외를 발생할 수 있는 예외를 적어주면 됨
2. 예외가 여러 개일 경우에는 쉼표(,)로 구분
```java
void method() throws Exception1, Exception2, ..., ExceptionN {
      // 메서드 내용
}
```
  - 예외 발생 키워드 : throw
  - 예외를 메서드에 선언 키워드 : throws

3. 모든 예외의 최고조상인 Exception 클래스를 메서드에 선언하면, 해당 메서드는 모든 종류의 예외가 발생할 가능성이 있다는 뜻
```java
void method() throws Exception {
    // 메서드 내용
}
```
  - 이렇게 선언하면, 이 예외뿐 아니라 그 자손 타입의 예외까지도 발생할 수 있다는 점 주의
  - 오버라이딩 할 때는 단순히 선언된 예외의 개수가 아니라 상속관계까지 고려해야함

4. 예시
<div align="center">
<img src="https://github.com/sooyounghan/Java/assets/34672301/b9fab721-44c6-4205-a5e3-1b16d77812e0">
</div>

  - java.lang.Object클래스의 wait 메서드는 메서드 선언부에 InterruptedException이 키워드 throws와 함께 적혀져있음
  - 즉, 이 메서드는 InterruptedException이 발생할 수 있으니, 호출하고자 하는 메서드는 이 예외를 처리해줘야함을 의미
  - Throws:를 보면, wait 메서드에서 발생할 수 있는 예외 리스트와 언제 발생하는지에 대한 설명이 표시
  - 여기에서는 또 하나의 예외 (IllegalMonitorStateException) 존재
<div align="center">
<img src="https://github.com/sooyounghan/Java/assets/34672301/b1773d04-ee63-4623-a611-03c926b81672">
</div>

  - InterruptedException는 Exception 클래스의 자손이며, 따라서 반드시 처리해줘야하는 예외임을 알 수 있음
  - 따라서, wait 메서드 선언부에 throws와 함께 선언되어있음
<div align="center">
<img src="https://github.com/sooyounghan/Java/assets/34672301/2eb97244-4015-46be-8005-2e431a1dc07d">
</div>

  - IllegalMonitorStateException은 RuntimeException의 자손이므로 따로 예외처리를 해주지 않아도 되므로, wait 메서드 선언부에 적지 않은 것

5. 메서드에 예외를 선언할 때 일반적으로 RuntimeException 클래스들은 적지 않음
   - 메서드 선언부의 throws에 선언한다고 해서 문제가 발생하지 않지만, 보통 반드시 처리해줘야하는 예외들만 선언
  
6. 사실, 예외를 메서드의 throws에 명시하는 것은 예외를 처리하는 것이 아니라, 자신(예외가 발생할 가능성이 있는 메서드)을 호출한 메서드에게 예외를 전달하여 예외처리를 맡기는 것
7. 예외를 전달받은 메서드가 또 다시 자신을 호출한 메서드에게 전달할 수 있으며, 이런 식으로 계속 호출 스택에 있는 메서드들을 따라가다가 제일 마지막에 있는 main 메서드에서도 예외가 처리되지 않으면, main 메서드마저 종료되어 프로그램 전체가 종료

```java
class ExceptionEx12 {
	public static void main(String[] args) throws Exception {
		method1();	 // 같은 클래스내 static 멤버이므로 객체 생성없이 직접 호출 가능
  	}	// main

	static void method1() throws Exception {
		method2();
	}	// method1

	static void method2() throws Exception {
		throw new Exception();
	}	// method2
}
```
<div align="center">
<img src="https://github.com/sooyounghan/Java/assets/34672301/33e41f33-e1d8-48d0-b877-8072f422d811">
</div>

  - 프로그램 실행 도중 java.lang.Exception이 발생하여 비정상적으로 종료했다는 것과 예외가 발생했을 때 호출 스택(Call Stack)의 내용을 알 수 있음
```
A. 예외가 발생했을 때, 모두 3개의 메서드(main. method1, method2)가 호출 스택에 존재
B. 예외가 발생한 곳은 제일 윗줄에 있는 method2
C. main메서드가 method1()을, 그리고 method1()은 method2()를 호출했다는 것을 알 수 있음
```
  - method2()에서 throw new Exception(); 문장에 의해 예외를 강제적으로 발생했으나 try-catch 문으로 예외처리를 해주지 않았으므로, method2()는 종료
  - 예외를 자신이 호출한 method1()에게 넘겨주지만, 이 메서드에서도 예외처리를 해주지 않았으므로 main메서드에게 예외를 넘겨줌
  - 그러나 main 메서드에서조차 예외처리를 해주지 않았으므로 main 메서드가 종료되어 프로그램이 예외로 인해 비정상적으로 종료

8. 이처럼, 예외가 발생한 메서드에서 예외처리를 하지 않고 자신을 호출한 메서드에게 예외를 넘겨줄 수 있지만, 이것으로 예외가 처리된 것이 아닌 예외를 단순히 전달만 하는 것
9. 결국, 어느 한 곳에서는 반드시 try-catch문으로 예외처리를 해야함

-----
### 메서드에 예외 선언 예제
-----
```java
class ExceptionEx13 {
	public static void main(String[] args) {
		method1(); 	 // 같은 클래스내 static 멤버이므로 객체 생성없이 직접 호출 가능
  	}	// main

	static void method1() {
		try {
		     throw new Exception();
		} catch (Exception e) {
			System.out.println("method1메서드에서 예외가 처리되었습니다.");
			e.printStackTrace();
		}
	}	// method1
}
```
<div align="center">
<img src="https://github.com/sooyounghan/Java/assets/34672301/32bda792-82a9-4dc2-9d8d-9a0bc4df7a39">
</div>

  - 예외는 처리되었으며, 예외가 method1()에서 발생했으며, main 메서드가 method1()을 호출했음을 알 수 있음

```java
class ExceptionEx14 {
	public static void main(String[] args) {
		try  {
				method1();		
		} catch (Exception e)	{
				System.out.println("main메서드에서 예외가 처리되었습니다.");
				e.printStackTrace();
		}
	}	// main

	static void method1() throws Exception {
		throw new Exception();
	}	// method1()
} // class
```
<div align="center">
<img src="https://github.com/sooyounghan/Java/assets/34672301/4783c375-2c23-4f49-9786-27205a1ac475">
</div>

1. 첫 번째 예제 : 예외가 발생한 메서드(method1) 내에서 처리되어지면, 호출한 메서드(main)에서는 예외가 발생한 사실조차 모름
2. 두 번째 예제 : 예외가 발생한 메서드(method1)에서 예외를 처리하지 않고, 호출한 메서드(main)메서드로 넘겨주면, 호출한 메서드는 method1()을 호출한 라인에서 예외가 발생한 것으로 간주되어 이를 처리
3. 이처럼, 예외가 발생한 메서드 method1에서 예외 처리 가능, 예외가 발생한 메서드를 호출한 main 메서드에서 예외 처리 가능 또는 두 메서드가 예외 처리를 분담할 수 있음

```java
import java.io.*;

class ExceptionEx15 {
	public static void main(String[] args) {
        // command line에서 입력받은 값을 이름으로 갖는 파일 생성
		File f = createFile(args[0]);	
		System.out.println( f.getName() + " 파일이 성공적으로 생성되었습니다..");
	} // main

	static File createFile(String fileName) {
		try {
			if (fileName==null || fileName.equals(""))
				throw new Exception("파일 이름이 유효하지 않습니다.");
		} catch (Exception e) {
             // fileName이 부적절한 경우, 파일 이름을 '제목없음.txt'로 설정
			fileName = "제목없음.txt";	 
		} finally {
			File f = new File(fileName); // File클래스 객체 생성
			createNewFile(f);		     // 생성된 객체를 이용해 파일 생성
			return f;
		}
	}	// createFile

	static void createNewFile(File f) {
		try {
			f.createNewFile();		// 파일 생성
		} catch(Exception e){ }
	}	// createNewFile
} 
```
  - 예외가 발생한 메서드에서 직접 예외를 처리
  - createFile 메서드를 호출한 main 메서드에서는 예외 발생 사실을 모름
  - finally 블럭은 예외 발생 여부 관계 없이 파일 생성

```java
import java.io.*;

class ExceptionEx16 {
	public static void main(String[] args) 
	{
		try {
			File f = createFile(args[0]);
			System.out.println( f.getName()+" 파일이 성공적으로 생성되었습니다.");
		} catch (Exception e) {
			System.out.println(e.getMessage()+" 다시 입력해주시길 바랍니다.");
		}
	}	// main

	static File createFile(String fileName) throws Exception {
		if (fileName==null || fileName.equals(""))
			throw new Exception("파일 이름이 유효하지 않습니다.");
		File f = new File(fileName);		//  File클래스 객체를 만듬
        // File객체의 createNewFile메서드를 이용해 실제 파일 생성
		f.createNewFile();
		return f;		// 생성된 객체의 참조 반환
	}	// createFile
}	// Class
```

  - 예외가 발생한 createFile메서드에서 잘못 입력된 파일 이름을 임의로 처리하지 않고, 호출한 main 메서드에게 예외가 발생했음을 알려서 파일이름을 다시 입력 받음
  - createFile 메서드에 예외를 선언했으므로, File클래스의 createNewFile()에 대한 예외처리를 하지 않아도 되므로 createNewFile(File f) 메서드를 따로 만들지 않음

4. 첫 번째 예제 : 예외가 발생한 createFile 내에서 자체적으로 예외 처리
5. 두 번째 예제 : createFile메서드를 호출한 메서드(main 메서드)에서 처리
6. 이처럼, 예외가 발생한 메서드 내에서 자체적으로 처리해도 되는 것은 메서드 내에서 try-catch문을 사용해서 처리
7. 메서드 호출 시 넘겨받아야할 값을 다시 받아야하는 경우(메서드 내 자체적으로 해결이 안되는 경우)에는 예외를 메서드에 선언해서, 호출한 메서드에서 처리하도록 해야함




