-----
### 자원 정리1
-----
1. CallException (/tcp/autocloseable)
```java
package network.tcp.autocloseable;

public class CallException extends Exception {
    public CallException(String message) {
        super(message);
    }
}
```
2. CloseException (/tcp/autocloseable)
```java
package network.tcp.autocloseable;

public class CloseException extends Exception {
    public CloseException(String message) {
        super(message);
    }
}
```

3. ResourceV1 (/tcp/autocloseable)
```java
package network.tcp.autocloseable;

public class ResourceV1 {
    private String name;

    public ResourceV1(String name) {
        this.name = name;
    }

    public void call() { // 호출
        System.out.println(name + " call");
    }

    public void callEx() throws CallException { // CallException
        System.out.println(name + " call Ex");
        throw new CallException(name + " ex");
    }

    public void close() { // 자원 정리
        System.out.println(name + " close");
    }

    public void closeEx() throws CloseException { // CloseException
        System.out.println(name + " closeEx");
        throw new CloseException(name + " ex");
    }
}
```

  - call() : 정상 로직 호출
  - callEx() : 비정상 로직 호출 (CallException을 던짐)
  - close() : 정상 종료
  - closeEx() : 비정상 종료 (CloseException을 던짐)

4. ResourceCloseMainV1
```java
package network.tcp.autocloseable;

public class ResourceCloseMainV1 {
    public static void main(String[] args) {
        try {
            logic();
        } catch (CallException e) {
            System.out.println("CallException 예외 처리");
            throw new RuntimeException(e);
        } catch (CloseException e) {
            System.out.println("CloseException 예외 처리");
            throw new RuntimeException(e);
        }
    }

    private static void logic() throws CallException, CloseException {
        ResourceV1 resource1 = new ResourceV1("resource1");
        ResourceV1 resource2 = new ResourceV1("resource2");

        resource1.call();
        resource2.callEx(); // CallException

        System.out.println("자원 정리"); // 호출 되지 않음
        resource2.closeEx(); // 자원 정리 단계에서 CloseException
        resource1.closeEx();
    }
}
```
  - 서로 관련된 자원은 나중에 생성한 자원을 먼저 정리해야 함
  - 예를 들어, resource1을 생성하고, resource1의 정보를 활용해서 resource2를 생성한다면, 닫을 때는 그 반대인 resource2를 먼저 닫고, 그 다음에 resource1을 닫아야 함
    + resource2 입장에서 resouce1의 정보를 아직 참고하고 있기 때문임
  - 이 예제에서는 두 자원이 서로 관련이 없기 때문에, 생성과 종료 순서가 크게 상관이 없지만, resource1의 정보를 기반으로 resource2를 생성한다고 가정

5. 실행 결과
```
resource1 call
resource2 call Ex
CallException 예외 처리
Exception in thread "main" java.lang.RuntimeException: network.tcp.autoclosable.CallException: resource2 ex
	at network.tcp.autoclosable.ResourceCloseMainV1.main(ResourceCloseMainV1.java:9)
Caused by: network.tcp.autoclosable.CallException: resource2 ex
	at network.tcp.autoclosable.ResourceV1.callEx(ResourceV1.java:16)
	at network.tcp.autoclosable.ResourceCloseMainV1.logic(ResourceCloseMainV1.java:21)
	at network.tcp.autoclosable.ResourceCloseMainV1.main(ResourceCloseMainV1.java:6)
```
  - callEx() 호출하면서 예외 발생
  - 예외 때문에 자원 정리 코드가 정상 호출되지 않음
  - 즉, 예외가 발생하면 자원 정리가 되지 않는 문제 발생

-----
### 자원 정리2
-----
1. 예외가 발생하도 자원 정리가 되도록 설정
2. ResourceCloseMain2 (tcp/closeable)
```java
package network.tcp.autocloseable;

public class ResourceCloseMainV2 {
    public static void main(String[] args) {
        try {
            logic();
        } catch (CallException e) {
            System.out.println("CallException 예외 처리");
            throw new RuntimeException(e);
        } catch (CloseException e) { // CloseException을 받음
            System.out.println("CloseException 예외 처리");
            throw new RuntimeException(e);
        }
    }

    private static void logic() throws CallException, CloseException {
        ResourceV1 resource1 = null; // 초기 선언은 null로 초기화
        ResourceV1 resource2 = null; // 초기 선언은 null로 초기화

        try {
            // 객체를 생성하는 경우에도 예외 발생 가능성 존재하므로 try ~ catch ~ fianlly 문 안에 선언해야 함
            resource1 = new ResourceV1("resource1"); // 만약 예외가 발생하면,
            resource2 = new ResourceV1("resource2"); // resource1의 예외로 인해 생성되지 않음

            resource1.call();
            resource2.callEx(); // CallException
        } catch (CallException e) { // CallException 예외 처리
            System.out.println("ex: " + e);
            throw e; // 예외 던짐
        } finally {  // CallException 예외 처리 후, fianlly로 이동
            if(resource2 != null) { // 위의 객체 생성 예외 경우를 대비해, 조건문
                resource2.closeEx(); // 자원 정리 단계에서 CloseException 발생 -> CloseException이 던져짐 (CallException이 아님) -> resoruce1 자원 정리 불가
            }

            if(resource1 != null) { // 위의 객체 생성 예외 경우를 대비해, 조건문
                resource1.closeEx(); // 호출되지 않음
            }
        }
    }
}
```

3. 실행 결과
```
resource1 call
resource2 call Ex
ex: network.tcp.autoclosable.CallException: resource2 ex
resource2 closeEx
CloseException 예외 처리
Exception in thread "main" java.lang.RuntimeException: network.tcp.autoclosable.CloseException: resource2 ex
	at network.tcp.autoclosable.ResourceCloseMainV2.main(ResourceCloseMainV2.java:12)
Caused by: network.tcp.autoclosable.CloseException: resource2 ex
	at network.tcp.autoclosable.ResourceV1.closeEx(ResourceV1.java:25)
	at network.tcp.autoclosable.ResourceCloseMainV2.logic(ResourceCloseMainV2.java:32)
	at network.tcp.autoclosable.ResourceCloseMainV2.main(ResourceCloseMainV2.java:6)
```

4. Null 체크
   - finally 코드 블록을 사용해서 자원을 닫는 코드 항상 호출하도록 설정
   - 만약, resource2 객체를 생성하기 전에 에외가 발생하면 resource2는 null이므로 null 체크를 해야 함
   - resourc1의 경우에도 resource1을 생성하는 중에 예외가 발생한다면 null 체크 필요

5. 자원 정리 중 예외가 발생하는 문제
   - finally 코드 블록은 항상 호출되므로 자원이 잘 정리될 것 같지만, 이번에는 자원을 정리하는 중에 fianlly 코드 블록 안에 resource2.closeEx()를 호출하면서 예외 발생
   - 결과적으로, resource1.closeEx()는 호출되지 않음

6. 핵심 예외가 바뀌는 문제
   - 코드에서 발생한 핵심적 예외는 CallException (이 예외로 인해 문제발생)
   - 그런데 finally 코드 블록에서 자원을 정리하면서 CloseException 예외가 추가로 발생
   - 예외 때문에 자원을 정리하고 있는데, 자원 정리 중에 또 예외가 발생한 것
   - 💡 이 경우, logic()을 호출한 쪽에서는 핵심 예외인 CallException이 아니라 finally 블록에서 새로 생성된 CloseException을 받음 (핵심 예외가 사라짐)
   - 핵심 예외를 확인해야 제대로 된 문제를 찾을 수 있음 (자원을 닫는 중 발생한 예외는 부가 예외)

7. 정리
   - close() 시점에 실수로 예외를 던지면, 이후 다른 자원을 닫을 수 없는 문제발생
   - fianlly 블록 안에서 자원을 닫을 때 예외가 발생하면, 핵심 예외가 finally 에서 발생한 부가 예외로 바뀌어버리고, 핵심 예외가 사라짐

-----
### 자원 정리3
-----
1. try ~ catch를 사용해서 자원 중리 중 발생하는 예외 처리
2. ResourceCloseMainV3 (/tcp/autocloseable)
```java
package network.tcp.autocloseable;

public class ResourceCloseMainV3 {
    public static void main(String[] args) {
        try {
            logic();
        } catch (CallException e) {
            System.out.println("CallException 예외 처리");
            throw new RuntimeException(e);
        } catch (CloseException e) { // CloseException을 받음
            System.out.println("CloseException 예외 처리");
            throw new RuntimeException(e);
        }
    }

    private static void logic() throws CallException, CloseException {
        ResourceV1 resource1 = null; // 초기 선언은 null로 초기화
        ResourceV1 resource2 = null; // 초기 선언은 null로 초기화

        try {
            // 객체를 생성하는 경우에도 예외 발생 가능성 존재하므로 try ~ catch ~ fianlly 문 안에 선언해야 함
            resource1 = new ResourceV1("resource1"); // 만약 예외가 발생하면,
            resource2 = new ResourceV1("resource2"); // resource1의 예외로 인해 생성되지 않음

            resource1.call();
            resource2.callEx(); // CallException
        } catch (CallException e) { // CallException 예외 처리
            System.out.println("ex: " + e);
            throw e; // 예외 던짐
        } finally {  // CallException 예외 처리 후, fianlly로 이동
            if(resource2 != null) { // 위의 객체 생성 예외 경우를 대비해, 조건문
                try {
                    resource2.closeEx(); // 자원 정리 단계에서 CloseException 발생 -> CloseException이 던져짐 (CallException이 아님) -> resoruce1 자원 정리 불가
                } catch (CloseException e) {
                    // 자원 정리 단계에서 발생한 예외 : close()에서 발생한 예외 버리기. 필요하면 로깅 정도 표시
                    System.out.println("ex: " + e);
                }
            }

            if(resource1 != null) { // 위의 객체 생성 예외 경우를 대비해, 조건문
                try {
                    resource1.closeEx();
                } catch (CloseException e) {
                    System.out.println("ex: " + e);
                }
            }
        }
    }
}
```

   - finally 블럭에서 각 자원을 닫을 때도, 예외가 발생하면 예외를 잡아서 처리하도록 설정
   - 자원 정리 시점에 예외가 발생해도, 다음 자원 닫을 수 있음
   - 자원 정리 시점에 발생한 예외를 처리했기 때문에, 자원 정리 시점에 발생한 부가 예외가 핵심 예외를 가리지 않음
   - 자원 정리 시점에 발생한 예외는 당장 처리할 수 있는 부분이 없으므로, 로그를 남겨서 개발자가 인지하도록 하는 정도면 충분

3. 실행 결과
```
resource1 call
resource2 call Ex
ex: network.tcp.autoclosable.CallException: resource2 ex
resource2 closeEx
ex: network.tcp.autoclosable.CloseException: resource2 ex
resource1 closeEx
ex: network.tcp.autoclosable.CloseException: resource1 ex
CallException 예외 처리
Exception in thread "main" java.lang.RuntimeException: network.tcp.autoclosable.CallException: resource2 ex
	at network.tcp.autoclosable.ResourceCloseMainV3.main(ResourceCloseMainV3.java:9)
Caused by: network.tcp.autoclosable.CallException: resource2 ex
	at network.tcp.autoclosable.ResourceV1.callEx(ResourceV1.java:16)
	at network.tcp.autoclosable.ResourceCloseMainV3.logic(ResourceCloseMainV3.java:26)
	at network.tcp.autoclosable.ResourceCloseMainV3.main(ResourceCloseMainV3.java:6)
```
  - close() 시점에 실수로 에외를 던지면, 이후 다른 자원을 닫을 수 없는 문제 해결
  - finally 블럭 안에서 자원을 닫을 때 예외가 발생하면, 핵심 예외가 finally에서 발생한 부가 예외로 바뀌고, 핵심 예외가 사라지는 문제 해결

4. 보완 사항
   - resource 변수를 선언하면서 동시에 할당 불가 (try, finally 코드 블록과 변수 스코프가 다른 문제)
   - catch 이후 fianlly가 호출되어, 자원 정리가 조금 늦어짐
   - 실수로 close()를 호출하지 않을 가능성
   - close() 호출 순서를 보통 자원을 생성한 순서로 반대로 닫아야 함 (close() 호출 순서 실수 문제)

-----
### 자원 정리4
-----
1. try ~ with resources문 활용
2. ResourceV2 (/tcp/autocloseable)
```java
package network.tcp.autocloseable;

public class ResourceV2 implements AutoCloseable {
    private String name;

    public ResourceV2(String name) {
        this.name = name;
    }

    public void call() { // 호출
        System.out.println(name + " call");
    }

    public void callEx() throws CallException { // CallException
        System.out.println(name + " call Ex");
        throw new CallException(name + " ex");
    }

    @Override
    public void close() throws CloseException { // 자원 정리하면서 CloseException 발생
        System.out.println(name + " close");
        throw new CloseException(name + " ex");
    }
}
```
  - AutoCloseable 구현
  - close()는 항상 CloseException을 던짐

3. ResourceCloseMainV4
```java
package network.tcp.autocloseable;

public class ResourceCloseMainV4 {
    public static void main(String[] args) {
        try {
            logic();
        } catch (CallException e) {
            System.out.println("CallException 예외 처리");

            Throwable[] suppressed = e.getSuppressed(); // Suppressed 된 예외 추출 [e.addSuppressed() : 핵심 예외에 부가 예외를 넣어줌]
            for (Throwable throwable : suppressed) {
                System.out.println("Suppressed Ex = " + throwable);
                /*
                    결과 : Suppressed Ex = network.tcp.autocloseable.CloseException: resource2 ex
                          Suppressed Ex = network.tcp.autocloseable.CloseException: resource1 ex
                 */
            }
            
            throw new RuntimeException(e); // 발생 예외
        } catch (CloseException e) { // CloseException을 받음
            System.out.println("CloseException 예외 처리");
            throw new RuntimeException(e);
        }
    }

    private static void logic() throws CallException, CloseException {
        try (ResourceV2 resource1 = new ResourceV2("resource1");
             ResourceV2 resource2 = new ResourceV2("resource2");) {
            resource1.call();
            resource2.callEx();

            /*
                try ~ with ~ resource문 : AutoCloseable로 구현된 클래스 또는 AutoCloseable의 close() 호출
                    - 예외 발생 전에 자원 정리 먼저 실행
                    - resource2 -> resource1 순으로 정리
                    - 자원 정리 중에 발생한 예외는 부가 예외로 처리 (Suppressed)
             */
            // resource2.close(); 자동 처리
            // resource1.close(); 자동 처리

        } catch (CallException e) { // 핵심 예외는 CallException (Caused by), Java에서 CallException 안에 자원 정리 간 발생 예외를 넣음
            System.out.println("ex: " + e);
            throw e;
        }
    }
}
```

4. 실행 결과
```
resource1 call
resource2 call Ex
resource2 close
resource1 close
ex: network.tcp.autocloseable.CallException: resource2 ex
CallException 예외 처리
Suppressed Ex = network.tcp.autocloseable.CloseException: resource2 ex
Suppressed Ex = network.tcp.autocloseable.CloseException: resource1 ex
Exception in thread "main" java.lang.RuntimeException: network.tcp.autocloseable.CallException: resource2 ex
	at network.tcp.autocloseable.ResourceCloseMainV4.main(ResourceCloseMainV4.java:14)
Caused by: network.tcp.autocloseable.CallException: resource2 ex
	at network.tcp.autocloseable.ResourceV2.callEx(ResourceV2.java:16)
	at network.tcp.autocloseable.ResourceCloseMainV4.logic(ResourceCloseMainV4.java:25)
	at network.tcp.autocloseable.ResourceCloseMainV4.main(ResourceCloseMainV4.java:6)
	Suppressed: network.tcp.autocloseable.CloseException: resource2 ex
		at network.tcp.autocloseable.ResourceV2.close(ResourceV2.java:22)
		at network.tcp.autocloseable.ResourceCloseMainV4.logic(ResourceCloseMainV4.java:22)
		... 1 more
	Suppressed: network.tcp.autocloseable.CloseException: resource1 ex
		at network.tcp.autocloseable.ResourceV2.close(ResourceV2.java:22)
		at network.tcp.autocloseable.ResourceCloseMainV4.logic(ResourceCloseMainV4.java:22)
		... 1 more
```
  - try ~ with resources는 단순히 close()를 자동 호출해주는 정도 기능 제공이 아닌 다음 문제 해결

5. 해결 사항
   - 2가지 핵심 문제
     + close() 시점에 실수로 예외를 던지면, 이후 다른 자원을 닫을 수 없는 문제 해결
     + finally 블럭 안에서 자원을 닫을 때 예외가 발생하면, 핵심 예외가 finally에서 발생한 부가 예외로 바뀌어 버려, 핵심 예외가 사라지는 문제 해결

   - 4가지 부가 문제
     + resource 변수를 선언하면서 동시에 할당 불가한 문제 (try, finally 코드 블록과 변수 스코프가 다른 문제) 해결
     + catch 이후 fianlly가 호출되어, 자원 정리가 조금 늦어지는 문제 해결
     + 실수로 close()를 호출하지 않을 가능성 문제 해결
     + close() 호출 순서를 보통 자원을 생성한 순서로 반대로 닫아야 하는 문제 (close() 호출 순서 실수 문제) 해결

6. try ~ with resources 장점
   - 리소스 누수 방지
     + 모든 리소스가 제대로 닫히도록 보장
     + finally 블록을 적지 않거나, finally 블럭 안에서 자원 해제 코드를 누락하는 문제 예방

   - 코드 간결성 및 가독성 향상 : 명시적 close() 호출이 필요 없어 코드가 더 간결하고 읽기 쉬워짐
   - 스코프 범위 한정 : 예를 들어, 리소스로 사용되는 resource1, resource2 변수의 스코프가 try 블럭 안으로 한정되어, 코드 유지보수가 더 쉬워짐
   - 조금 더 빠른 자원 해제 : 기존에는 try → catch → finally 순으로, catch 이후에 자원 반납
     + try ~ with resources 구문은 try 블럭이 끝나면 즉시 close() 호출

   - 자원 정리 순서 : 먼저 선언한 자원을 나중에 정리
   - 부가 예외 포함

7. 💡 try ~ with resources 예외 처리와 부가 예외 포함
   - try ~ with resources를 사용하는 중 핵심 로직 예외와 자원을 정리하는 중 발생하는 부가 예외가 모두 발생하면?
   - try ~ with resources는 핵심 예외를 반환
   - 부가 예외는 핵심 예외 안에 Suppressed로 담아서 반환
   - 자원 정리 중 발생한 부가 예외를 e.getSuppressed()를 통해 활용 가능
   - 즉, try ~ with resources를 사용하면 핵심 예외를 반환하면서, 동시에 부가 예외도 필요하면 확인 가능

8. 자바 예외에는 e.addSuppressed(ex)라는 메서드 존재 : 예외 안에 참고할 에외를 담아둘 수 있으며, try ~ with resources와 함께 등장
